# 第 7 章：错误处理

在本章中，我们将探讨 Rust 的错误处理机制。编写健壮的程序需要妥善处理各种异常情况，Rust 提供了一套安全、清晰的错误处理系统，区分可恢复错误和不可恢复错误，帮助程序员明确处理各种错误情况。通过学习本章内容，你将能够编写出更可靠、更健壮的 Rust 程序。

**学习目标：**

- 掌握使用 Result<T, E> 处理可恢复错误的方法
- 理解 panic! 及其触发不可恢复错误的机制
- 学习错误传播技巧，简化错误处理代码
- 了解何时使用 panic! 和何时使用 Result
- 掌握如何创建自定义错误类型

## 7.1 可恢复错误与 Result<T, E>

大多数错误并不需要程序完全停止。例如，尝试打开一个不存在的文件是常见的错误情况，我们可能只需要向用户报告问题，而不是终止整个程序。这类情况就是"可恢复错误"。

Rust 使用 `Result<T, E>` 枚举处理可恢复错误：

```rust
enum Result<T, E> {
    Ok(T),   // 操作成功，包含成功值
    Err(E),  // 操作失败，包含错误信息
}
```

### 使用 Result 类型

`Result<T, E>` 是一个泛型枚举，其中：

- `T` 是操作成功时包含的值的类型
- `E` 是操作失败时包含的错误的类型

```rust
use std::fs::File;

fn main() {
    let file_result = File::open("hello.txt");

    // 使用 match 处理 Result
    let file = match file_result {
        Ok(file) => file,
        Err(error) => {
            println!("打开文件时出错: {:?}", error);
            return;
        }
    };

    println!("文件打开成功: {:?}", file);
}
```

在这个例子中，如果文件打开成功，`file_result` 将包含 `Ok` 变体和打开的文件句柄。如果操作失败，它将包含 `Err` 变体和描述错误的信息。

### 匹配不同类型的错误

错误类型通常包含有用的信息，可以帮助我们了解错误原因。通过嵌套的 `match` 表达式，我们可以根据不同类型的错误采取不同的行动：

```rust
use std::fs::File;
use std::io::ErrorKind;

fn main() {
    let file_result = File::open("hello.txt");

    let file = match file_result {
        Ok(file) => file,
        Err(error) => match error.kind() {
            ErrorKind::NotFound => {
                println!("文件不存在，正在创建...");
                match File::create("hello.txt") {
                    Ok(new_file) => new_file,
                    Err(create_error) => {
                        panic!("创建文件时出错: {:?}", create_error);
                    }
                }
            },
            ErrorKind::PermissionDenied => {
                println!("没有权限打开文件");
                return;
            },
            other_error => {
                println!("打开文件时发生其他错误: {:?}", other_error);
                return;
            }
        },
    };

    println!("文件操作成功: {:?}", file);
}
```

这个例子展示了如何区分不同的错误类型，并针对每种情况采取适当的措施。

### 错误处理的简写: unwrap 和 expect

`Result<T, E>` 提供了一些便捷方法，简化常见的错误处理模式：

```rust
use std::fs::File;

fn main() {
    // unwrap: 如果 Result 是 Ok，返回 Ok 中的值；如果是 Err，调用 panic!
    let file = File::open("hello.txt").unwrap();

    // expect: 类似 unwrap，但允许自定义 panic 消息
    let file = File::open("hello.txt").expect("无法打开文件 hello.txt");
}
```

`unwrap` 和 `expect` 在以下情况下很有用：

- 原型开发阶段，尚未确定完整的错误处理策略
- 测试代码中，简化错误处理
- 确信操作不会失败的场景
- 有相应的处理机制确保操作不会失败

### 使用 ? 运算符传播错误

当函数内部出现错误时，通常需要将错误传递给调用者处理。`?` 运算符提供了一种简洁的方式来实现这一点：

```rust
use std::fs::File;
use std::io::{self, Read};

fn read_file(path: &str) -> Result<String, io::Error> {
    let mut file = File::open(path)?; // 如果 Err，立即返回该错误

    let mut content = String::new();
    file.read_to_string(&mut content)?; // 如果 Err，立即返回该错误

    Ok(content) // 成功时返回包装在 Ok 中的内容
}

fn main() {
    let result = read_file("hello.txt");

    match result {
        Ok(content) => println!("文件内容: {}", content),
        Err(error) => println!("读取文件出错: {}", error),
    }
}
```

`?` 运算符的作用：

1. 如果 `Result` 是 `Ok`，则获取 `Ok` 中的值并继续执行
2. 如果 `Result` 是 `Err`，则将错误作为当前函数的返回值
3. 它还会自动进行错误类型转换（如果实现了 `From` trait）

### ? 运算符的链式调用

`?` 运算符可以链式调用，使代码更加简洁：

```rust
use std::fs::File;
use std::io::{self, Read};

fn read_file(path: &str) -> Result<String, io::Error> {
    let mut content = String::new();

    // 链式调用 ? 运算符
    File::open(path)?.read_to_string(&mut content)?;

    Ok(content)
}
```

### ? 运算符在 main 函数中的使用

从 Rust 1.26 开始，`main` 函数可以返回 `Result`，这允许在 `main` 中使用 `?` 运算符：

```rust
use std::fs::File;
use std::io;

fn main() -> Result<(), io::Error> {
    let mut file = File::open("hello.txt")?;
    // 处理文件...
    Ok(())
}
```

这种模式非常适合编写简单的命令行工具，可以直接在顶层使用 `?` 进行错误传播。

### 组合多个结果

当处理多个可能失败的操作时，可以使用 `Result` 的组合方法：

```rust
use std::fs;
use std::io;

fn copy_file(source: &str, target: &str) -> Result<(), io::Error> {
    // 这里使用 and_then 来组合操作
    fs::read_to_string(source)
        .and_then(|content| fs::write(target, content))
        .map_err(|error| {
            println!("复制文件时出错: {}", error);
            error
        })
}
```

常用的 `Result` 组合方法包括：

- `and_then`: 只有当 `Result` 是 `Ok` 时才执行函数
- `map`: 转换 `Ok` 中的值
- `map_err`: 转换 `Err` 中的错误
- `or_else`: 只有当 `Result` 是 `Err` 时才执行函数

## 7.2 不可恢复错误与 panic!宏

某些错误情况是无法合理恢复的，例如访问超出数组边界的元素。对于这些情况，Rust 提供了 `panic!` 宏，终止程序执行并提供出错信息。

### panic! 的基本用法

调用 `panic!` 宏会导致程序终止，打印错误消息，展开栈（unwind the stack），并清理资源：

```rust
fn main() {
    panic!("发生严重错误!");
}
```

输出：

```
thread 'main' panicked at '发生严重错误!', src/main.rs:2:5
```

### panic! 的触发条件

除了显式调用 `panic!` 外，以下情况也会导致 panic：

1. 数组越界访问：

```rust
fn main() {
    let v = vec![1, 2, 3];
    let out_of_bounds = &v[99]; // 这会导致 panic
}
```

2. 除以零：

```rust
fn main() {
    let x = 5;
    let y = 0;
    let z = x / y; // 这会导致 panic
}
```

3. 断言失败：

```rust
fn main() {
    let age = 20;
    assert!(age > 30, "年龄必须大于30岁"); // 断言失败导致 panic
}
```

### 调用栈回溯

当 panic 发生时，Rust 会展示调用栈回溯（backtrace），帮助你定位问题源头：

```rust
fn main() {
    函数a();
}

fn 函数a() {
    函数b();
}

fn 函数b() {
    函数c();
}

fn 函数c() {
    panic!("在函数c中发生了错误");
}
```

运行这段代码会显示从 `main` 到 `函数c` 的调用链，帮助定位问题。

要查看完整的回溯信息，可以设置环境变量 `RUST_BACKTRACE=1`：

```bash
$ RUST_BACKTRACE=1 cargo run
```

### panic! 的两种执行模式

Rust 中的 panic 有两种处理模式：

1. **展开（unwinding）**：默认行为，Rust 会回溯栈，清理每个函数的数据
2. **终止（abort）**：立即终止程序，不清理数据，由操作系统回收资源

可以在 `Cargo.toml` 中配置 panic 行为：

```toml
[profile.release]
panic = "abort"
```

### 恐慌安全代码

编写"恐慌安全"的代码意味着即使在 panic 发生时也不会留下无效或不一致的数据结构：

```rust
struct 计数器 {
    值: u32,
}

impl 计数器 {
    fn 增加(&mut self) {
        // 即使在发生 panic 时，这个简单赋值也是原子的，不会留下损坏的状态
        self.值 += 1;
    }

    fn 复杂操作(&mut self) {
        // 对于复杂操作，应考虑使用 std::panic::catch_unwind 或者
        // 确保操作完整性，避免部分修改
        self.值 += 1;

        if self.值 == 10 {
            panic!("达到最大值");
            // 在这个简单例子中，值已经修改，但状态仍然有效
        }

        self.值 += 1;
    }
}
```

在需要绝对保证不会有 panic 发生的代码中，可以使用 `std::panic::catch_unwind` 捕获 panic：

```rust
use std::panic;

fn main() {
    let result = panic::catch_unwind(|| {
        println!("正在执行可能 panic 的代码");
        panic!("啊哦");
    });

    if result.is_err() {
        println!("捕获到 panic，继续执行");
    }

    println!("程序继续运行");
}
```

不过，`catch_unwind` 主要用于：

- 嵌入式场景中保护外部调用
- 线程池中隔离任务失败
- 测试框架捕获测试 panic

它不应该作为常规错误处理的替代品。
